
Mon Mar  8 18:30:02 CST 2021
Traceback (most recent call last):
  File "/home/hlf/crontab/zstuAutoFillOut.py", line 77, in <module>
    zs.login1()
  File "/home/hlf/crontab/zstuAutoFillOut.py", line 42, in login1
    enter(self.wait,'2019329621160','//*[@id="app"]/div/div[1]/div/div/div/div/div/div/div/div[2]/div[2]/div[1]/div/input')
  File "/home/hlf/crontab/zstuAutoFillOut.py", line 21, in enter
    (By.XPATH, path)))
  File "/home/hlf/.local/lib/python3.6/site-packages/selenium/webdriver/support/wait.py", line 80, in until
    raise TimeoutException(message, screen, stacktrace)
selenium.common.exceptions.TimeoutException: Message: 


During handling of the above exception, another exception occurred:

Traceback (most recent call last):
  File "/home/hlf/crontab/zstuAutoFillOut.py", line 85, in <module>
    zs.run()
  File "/home/hlf/crontab/zstuAutoFillOut.py", line 55, in run
    click(self.wait,'//*[@id="col_2_row_14"]/div/div/div/div/div[1]/div/div[1]')
  File "/home/hlf/crontab/zstuAutoFillOut.py", line 16, in click
    (By.XPATH, path)))
  File "/home/hlf/.local/lib/python3.6/site-packages/selenium/webdriver/support/wait.py", line 80, in until
    raise TimeoutException(message, screen, stacktrace)
selenium.common.exceptions.TimeoutException: Message: 

-----------------------------------------------------------------------------------
-----------------------------------------------------------------------------------
-----------------------------------------------------------------------------------
-----------------------------------------------------------------------------------
-----------------------------------------------------------------------------------

Mon Mar  8 17:30:01 CST 2021
Traceback (most recent call last):
  File "/home/hlf/crontab/zstuAutoFillOut.py", line 77, in <module>
    zs.login1()
  File "/home/hlf/crontab/zstuAutoFillOut.py", line 42, in login1
    enter(self.wait,'2019329621160','//*[@id="app"]/div/div[1]/div/div/div/div/div/div/div/div[2]/div[2]/div[1]/div/input')
  File "/home/hlf/crontab/zstuAutoFillOut.py", line 21, in enter
    (By.XPATH, path)))
  File "/home/hlf/.local/lib/python3.6/site-packages/selenium/webdriver/support/wait.py", line 80, in until
    raise TimeoutException(message, screen, stacktrace)
selenium.common.exceptions.TimeoutException: Message: 


During handling of the above exception, another exception occurred:

Traceback (most recent call last):
  File "/home/hlf/crontab/zstuAutoFillOut.py", line 85, in <module>
    zs.run()
  File "/home/hlf/crontab/zstuAutoFillOut.py", line 55, in run
    click(self.wait,'//*[@id="col_2_row_14"]/div/div/div/div/div[1]/div/div[1]')
  File "/home/hlf/crontab/zstuAutoFillOut.py", line 16, in click
    (By.XPATH, path)))
  File "/home/hlf/.local/lib/python3.6/site-packages/selenium/webdriver/support/wait.py", line 80, in until
    raise TimeoutException(message, screen, stacktrace)
selenium.common.exceptions.TimeoutException: Message: 

-----------------------------------------------------------------------------------
-----------------------------------------------------------------------------------
-----------------------------------------------------------------------------------
-----------------------------------------------------------------------------------
-----------------------------------------------------------------------------------

Mon Mar  8 16:30:02 CST 2021
Traceback (most recent call last):
  File "/home/hlf/crontab/zstuAutoFillOut.py", line 77, in <module>
    zs.login1()
  File "/home/hlf/crontab/zstuAutoFillOut.py", line 42, in login1
    enter(self.wait,'2019329621160','//*[@id="app"]/div/div[1]/div/div/div/div/div/div/div/div[2]/div[2]/div[1]/div/input')
  File "/home/hlf/crontab/zstuAutoFillOut.py", line 21, in enter
    (By.XPATH, path)))
  File "/home/hlf/.local/lib/python3.6/site-packages/selenium/webdriver/support/wait.py", line 80, in until
    raise TimeoutException(message, screen, stacktrace)
selenium.common.exceptions.TimeoutException: Message: 


During handling of the above exception, another exception occurred:

Traceback (most recent call last):
  File "/home/hlf/crontab/zstuAutoFillOut.py", line 85, in <module>
    zs.run()
  File "/home/hlf/crontab/zstuAutoFillOut.py", line 55, in run
    click(self.wait,'//*[@id="col_2_row_14"]/div/div/div/div/div[1]/div/div[1]')
  File "/home/hlf/crontab/zstuAutoFillOut.py", line 16, in click
    (By.XPATH, path)))
  File "/home/hlf/.local/lib/python3.6/site-packages/selenium/webdriver/support/wait.py", line 80, in until
    raise TimeoutException(message, screen, stacktrace)
selenium.common.exceptions.TimeoutException: Message: 

-----------------------------------------------------------------------------------
-----------------------------------------------------------------------------------
-----------------------------------------------------------------------------------
-----------------------------------------------------------------------------------
-----------------------------------------------------------------------------------

Mon Mar  8 15:30:01 CST 2021
Traceback (most recent call last):
  File "/home/hlf/crontab/zstuAutoFillOut.py", line 77, in <module>
    zs.login1()
  File "/home/hlf/crontab/zstuAutoFillOut.py", line 42, in login1
    enter(self.wait,'2019329621160','//*[@id="app"]/div/div[1]/div/div/div/div/div/div/div/div[2]/div[2]/div[1]/div/input')
  File "/home/hlf/crontab/zstuAutoFillOut.py", line 21, in enter
    (By.XPATH, path)))
  File "/home/hlf/.local/lib/python3.6/site-packages/selenium/webdriver/support/wait.py", line 80, in until
    raise TimeoutException(message, screen, stacktrace)
selenium.common.exceptions.TimeoutException: Message: 


During handling of the above exception, another exception occurred:

Traceback (most recent call last):
  File "/home/hlf/crontab/zstuAutoFillOut.py", line 85, in <module>
    zs.run()
  File "/home/hlf/crontab/zstuAutoFillOut.py", line 55, in run
    click(self.wait,'//*[@id="col_2_row_14"]/div/div/div/div/div[1]/div/div[1]')
  File "/home/hlf/crontab/zstuAutoFillOut.py", line 16, in click
    (By.XPATH, path)))
  File "/home/hlf/.local/lib/python3.6/site-packages/selenium/webdriver/support/wait.py", line 80, in until
    raise TimeoutException(message, screen, stacktrace)
selenium.common.exceptions.TimeoutException: Message: 

-----------------------------------------------------------------------------------
-----------------------------------------------------------------------------------
-----------------------------------------------------------------------------------
-----------------------------------------------------------------------------------
-----------------------------------------------------------------------------------

Mon Mar  8 14:30:01 CST 2021
Traceback (most recent call last):
  File "/home/hlf/crontab/zstuAutoFillOut.py", line 77, in <module>
    zs.login1()
  File "/home/hlf/crontab/zstuAutoFillOut.py", line 42, in login1
    enter(self.wait,'2019329621160','//*[@id="app"]/div/div[1]/div/div/div/div/div/div/div/div[2]/div[2]/div[1]/div/input')
  File "/home/hlf/crontab/zstuAutoFillOut.py", line 21, in enter
    (By.XPATH, path)))
  File "/home/hlf/.local/lib/python3.6/site-packages/selenium/webdriver/support/wait.py", line 80, in until
    raise TimeoutException(message, screen, stacktrace)
selenium.common.exceptions.TimeoutException: Message: 


During handling of the above exception, another exception occurred:

Traceback (most recent call last):
  File "/home/hlf/crontab/zstuAutoFillOut.py", line 85, in <module>
    zs.run()
  File "/home/hlf/crontab/zstuAutoFillOut.py", line 55, in run
    click(self.wait,'//*[@id="col_2_row_14"]/div/div/div/div/div[1]/div/div[1]')
  File "/home/hlf/crontab/zstuAutoFillOut.py", line 16, in click
    (By.XPATH, path)))
  File "/home/hlf/.local/lib/python3.6/site-packages/selenium/webdriver/support/wait.py", line 80, in until
    raise TimeoutException(message, screen, stacktrace)
selenium.common.exceptions.TimeoutException: Message: 

-----------------------------------------------------------------------------------
-----------------------------------------------------------------------------------
-----------------------------------------------------------------------------------
-----------------------------------------------------------------------------------
-----------------------------------------------------------------------------------

Mon Mar  8 13:30:02 CST 2021
Traceback (most recent call last):
  File "/home/hlf/crontab/zstuAutoFillOut.py", line 77, in <module>
    zs.login1()
  File "/home/hlf/crontab/zstuAutoFillOut.py", line 42, in login1
    enter(self.wait,'2019329621160','//*[@id="app"]/div/div[1]/div/div/div/div/div/div/div/div[2]/div[2]/div[1]/div/input')
  File "/home/hlf/crontab/zstuAutoFillOut.py", line 21, in enter
    (By.XPATH, path)))
  File "/home/hlf/.local/lib/python3.6/site-packages/selenium/webdriver/support/wait.py", line 80, in until
    raise TimeoutException(message, screen, stacktrace)
selenium.common.exceptions.TimeoutException: Message: 


During handling of the above exception, another exception occurred:

Traceback (most recent call last):
  File "/home/hlf/crontab/zstuAutoFillOut.py", line 85, in <module>
    zs.run()
  File "/home/hlf/crontab/zstuAutoFillOut.py", line 53, in run
    click(self.wait,'//*[@id="app"]/div/div[1]/div/div/div/div/div[1]/div/div/div/div[2]/div/div/div[3]/div/div/div[5]/div/div/div[3]')
  File "/home/hlf/crontab/zstuAutoFillOut.py", line 16, in click
    (By.XPATH, path)))
  File "/home/hlf/.local/lib/python3.6/site-packages/selenium/webdriver/support/wait.py", line 80, in until
    raise TimeoutException(message, screen, stacktrace)
selenium.common.exceptions.TimeoutException: Message: 

-----------------------------------------------------------------------------------
-----------------------------------------------------------------------------------
-----------------------------------------------------------------------------------
-----------------------------------------------------------------------------------
-----------------------------------------------------------------------------------

Mon Mar  8 12:30:01 CST 2021
Traceback (most recent call last):
  File "/home/hlf/crontab/zstuAutoFillOut.py", line 77, in <module>
    zs.login1()
  File "/home/hlf/crontab/zstuAutoFillOut.py", line 42, in login1
    enter(self.wait,'2019329621160','//*[@id="app"]/div/div[1]/div/div/div/div/div/div/div/div[2]/div[2]/div[1]/div/input')
  File "/home/hlf/crontab/zstuAutoFillOut.py", line 21, in enter
    (By.XPATH, path)))
  File "/home/hlf/.local/lib/python3.6/site-packages/selenium/webdriver/support/wait.py", line 80, in until
    raise TimeoutException(message, screen, stacktrace)
selenium.common.exceptions.TimeoutException: Message: 


During handling of the above exception, another exception occurred:

Traceback (most recent call last):
  File "/home/hlf/crontab/zstuAutoFillOut.py", line 85, in <module>
    zs.run()
  File "/home/hlf/crontab/zstuAutoFillOut.py", line 55, in run
    click(self.wait,'//*[@id="col_2_row_14"]/div/div/div/div/div[1]/div/div[1]')
  File "/home/hlf/crontab/zstuAutoFillOut.py", line 16, in click
    (By.XPATH, path)))
  File "/home/hlf/.local/lib/python3.6/site-packages/selenium/webdriver/support/wait.py", line 80, in until
    raise TimeoutException(message, screen, stacktrace)
selenium.common.exceptions.TimeoutException: Message: 

-----------------------------------------------------------------------------------
-----------------------------------------------------------------------------------
-----------------------------------------------------------------------------------
-----------------------------------------------------------------------------------
-----------------------------------------------------------------------------------

Mon Mar  8 11:30:01 CST 2021
Traceback (most recent call last):
  File "/home/hlf/crontab/zstuAutoFillOut.py", line 77, in <module>
    zs.login1()
  File "/home/hlf/crontab/zstuAutoFillOut.py", line 42, in login1
    enter(self.wait,'2019329621160','//*[@id="app"]/div/div[1]/div/div/div/div/div/div/div/div[2]/div[2]/div[1]/div/input')
  File "/home/hlf/crontab/zstuAutoFillOut.py", line 21, in enter
    (By.XPATH, path)))
  File "/home/hlf/.local/lib/python3.6/site-packages/selenium/webdriver/support/wait.py", line 80, in until
    raise TimeoutException(message, screen, stacktrace)
selenium.common.exceptions.TimeoutException: Message: 


During handling of the above exception, another exception occurred:

Traceback (most recent call last):
  File "/home/hlf/crontab/zstuAutoFillOut.py", line 85, in <module>
    zs.run()
  File "/home/hlf/crontab/zstuAutoFillOut.py", line 53, in run
    click(self.wait,'//*[@id="app"]/div/div[1]/div/div/div/div/div[1]/div/div/div/div[2]/div/div/div[3]/div/div/div[5]/div/div/div[3]')
  File "/home/hlf/crontab/zstuAutoFillOut.py", line 16, in click
    (By.XPATH, path)))
  File "/home/hlf/.local/lib/python3.6/site-packages/selenium/webdriver/support/wait.py", line 80, in until
    raise TimeoutException(message, screen, stacktrace)
selenium.common.exceptions.TimeoutException: Message: 

-----------------------------------------------------------------------------------
-----------------------------------------------------------------------------------
-----------------------------------------------------------------------------------
-----------------------------------------------------------------------------------
-----------------------------------------------------------------------------------

Mon Mar  8 10:30:02 CST 2021
Traceback (most recent call last):
  File "/home/hlf/crontab/zstuAutoFillOut.py", line 77, in <module>
    zs.login1()
  File "/home/hlf/crontab/zstuAutoFillOut.py", line 42, in login1
    enter(self.wait,'2019329621160','//*[@id="app"]/div/div[1]/div/div/div/div/div/div/div/div[2]/div[2]/div[1]/div/input')
  File "/home/hlf/crontab/zstuAutoFillOut.py", line 21, in enter
    (By.XPATH, path)))
  File "/home/hlf/.local/lib/python3.6/site-packages/selenium/webdriver/support/wait.py", line 80, in until
    raise TimeoutException(message, screen, stacktrace)
selenium.common.exceptions.TimeoutException: Message: 


During handling of the above exception, another exception occurred:

Traceback (most recent call last):
  File "/home/hlf/crontab/zstuAutoFillOut.py", line 85, in <module>
    zs.run()
  File "/home/hlf/crontab/zstuAutoFillOut.py", line 55, in run
    click(self.wait,'//*[@id="col_2_row_14"]/div/div/div/div/div[1]/div/div[1]')
  File "/home/hlf/crontab/zstuAutoFillOut.py", line 16, in click
    (By.XPATH, path)))
  File "/home/hlf/.local/lib/python3.6/site-packages/selenium/webdriver/support/wait.py", line 80, in until
    raise TimeoutException(message, screen, stacktrace)
selenium.common.exceptions.TimeoutException: Message: 

-----------------------------------------------------------------------------------
-----------------------------------------------------------------------------------
-----------------------------------------------------------------------------------
-----------------------------------------------------------------------------------
-----------------------------------------------------------------------------------

Mon Mar  8 09:30:01 CST 2021
Traceback (most recent call last):
  File "/home/hlf/crontab/zstuAutoFillOut.py", line 77, in <module>
    zs.login1()
  File "/home/hlf/crontab/zstuAutoFillOut.py", line 42, in login1
    enter(self.wait,'2019329621160','//*[@id="app"]/div/div[1]/div/div/div/div/div/div/div/div[2]/div[2]/div[1]/div/input')
  File "/home/hlf/crontab/zstuAutoFillOut.py", line 21, in enter
    (By.XPATH, path)))
  File "/home/hlf/.local/lib/python3.6/site-packages/selenium/webdriver/support/wait.py", line 80, in until
    raise TimeoutException(message, screen, stacktrace)
selenium.common.exceptions.TimeoutException: Message: 


During handling of the above exception, another exception occurred:

Traceback (most recent call last):
  File "/home/hlf/crontab/zstuAutoFillOut.py", line 85, in <module>
    zs.run()
  File "/home/hlf/crontab/zstuAutoFillOut.py", line 55, in run
    click(self.wait,'//*[@id="col_2_row_14"]/div/div/div/div/div[1]/div/div[1]')
  File "/home/hlf/crontab/zstuAutoFillOut.py", line 16, in click
    (By.XPATH, path)))
  File "/home/hlf/.local/lib/python3.6/site-packages/selenium/webdriver/support/wait.py", line 80, in until
    raise TimeoutException(message, screen, stacktrace)
selenium.common.exceptions.TimeoutException: Message: 

-----------------------------------------------------------------------------------
-----------------------------------------------------------------------------------
-----------------------------------------------------------------------------------
-----------------------------------------------------------------------------------
-----------------------------------------------------------------------------------

Mon Mar  8 08:30:01 CST 2021
Traceback (most recent call last):
  File "/home/hlf/crontab/zstuAutoFillOut.py", line 77, in <module>
    zs.login1()
  File "/home/hlf/crontab/zstuAutoFillOut.py", line 42, in login1
    enter(self.wait,'2019329621160','//*[@id="app"]/div/div[1]/div/div/div/div/div/div/div/div[2]/div[2]/div[1]/div/input')
  File "/home/hlf/crontab/zstuAutoFillOut.py", line 21, in enter
    (By.XPATH, path)))
  File "/home/hlf/.local/lib/python3.6/site-packages/selenium/webdriver/support/wait.py", line 80, in until
    raise TimeoutException(message, screen, stacktrace)
selenium.common.exceptions.TimeoutException: Message: 


During handling of the above exception, another exception occurred:

Traceback (most recent call last):
  File "/home/hlf/crontab/zstuAutoFillOut.py", line 85, in <module>
    zs.run()
  File "/home/hlf/crontab/zstuAutoFillOut.py", line 55, in run
    click(self.wait,'//*[@id="col_2_row_14"]/div/div/div/div/div[1]/div/div[1]')
  File "/home/hlf/crontab/zstuAutoFillOut.py", line 16, in click
    (By.XPATH, path)))
  File "/home/hlf/.local/lib/python3.6/site-packages/selenium/webdriver/support/wait.py", line 80, in until
    raise TimeoutException(message, screen, stacktrace)
selenium.common.exceptions.TimeoutException: Message: 

-----------------------------------------------------------------------------------
-----------------------------------------------------------------------------------
-----------------------------------------------------------------------------------
-----------------------------------------------------------------------------------
-----------------------------------------------------------------------------------

Mon Mar  8 07:30:02 CST 2021
Traceback (most recent call last):
  File "/home/hlf/crontab/zstuAutoFillOut.py", line 77, in <module>
    zs.login1()
  File "/home/hlf/crontab/zstuAutoFillOut.py", line 42, in login1
    enter(self.wait,'2019329621160','//*[@id="app"]/div/div[1]/div/div/div/div/div/div/div/div[2]/div[2]/div[1]/div/input')
  File "/home/hlf/crontab/zstuAutoFillOut.py", line 21, in enter
    (By.XPATH, path)))
  File "/home/hlf/.local/lib/python3.6/site-packages/selenium/webdriver/support/wait.py", line 80, in until
    raise TimeoutException(message, screen, stacktrace)
selenium.common.exceptions.TimeoutException: Message: 


During handling of the above exception, another exception occurred:

Traceback (most recent call last):
  File "/home/hlf/crontab/zstuAutoFillOut.py", line 85, in <module>
    zs.run()
  File "/home/hlf/crontab/zstuAutoFillOut.py", line 55, in run
    click(self.wait,'//*[@id="col_2_row_14"]/div/div/div/div/div[1]/div/div[1]')
  File "/home/hlf/crontab/zstuAutoFillOut.py", line 16, in click
    (By.XPATH, path)))
  File "/home/hlf/.local/lib/python3.6/site-packages/selenium/webdriver/support/wait.py", line 80, in until
    raise TimeoutException(message, screen, stacktrace)
selenium.common.exceptions.TimeoutException: Message: 

-----------------------------------------------------------------------------------
-----------------------------------------------------------------------------------
-----------------------------------------------------------------------------------
-----------------------------------------------------------------------------------
-----------------------------------------------------------------------------------

Mon Mar  8 06:30:02 CST 2021
Traceback (most recent call last):
  File "/home/hlf/crontab/zstuAutoFillOut.py", line 77, in <module>
    zs.login1()
  File "/home/hlf/crontab/zstuAutoFillOut.py", line 42, in login1
    enter(self.wait,'2019329621160','//*[@id="app"]/div/div[1]/div/div/div/div/div/div/div/div[2]/div[2]/div[1]/div/input')
  File "/home/hlf/crontab/zstuAutoFillOut.py", line 21, in enter
    (By.XPATH, path)))
  File "/home/hlf/.local/lib/python3.6/site-packages/selenium/webdriver/support/wait.py", line 80, in until
    raise TimeoutException(message, screen, stacktrace)
selenium.common.exceptions.TimeoutException: Message: 


During handling of the above exception, another exception occurred:

Traceback (most recent call last):
  File "/home/hlf/crontab/zstuAutoFillOut.py", line 85, in <module>
    zs.run()
  File "/home/hlf/crontab/zstuAutoFillOut.py", line 55, in run
    click(self.wait,'//*[@id="col_2_row_14"]/div/div/div/div/div[1]/div/div[1]')
  File "/home/hlf/crontab/zstuAutoFillOut.py", line 16, in click
    (By.XPATH, path)))
  File "/home/hlf/.local/lib/python3.6/site-packages/selenium/webdriver/support/wait.py", line 80, in until
    raise TimeoutException(message, screen, stacktrace)
selenium.common.exceptions.TimeoutException: Message: 

-----------------------------------------------------------------------------------
-----------------------------------------------------------------------------------
-----------------------------------------------------------------------------------
-----------------------------------------------------------------------------------
-----------------------------------------------------------------------------------

Mon Mar  8 05:30:01 CST 2021
Traceback (most recent call last):
  File "/home/hlf/crontab/zstuAutoFillOut.py", line 77, in <module>
    zs.login1()
  File "/home/hlf/crontab/zstuAutoFillOut.py", line 42, in login1
    enter(self.wait,'2019329621160','//*[@id="app"]/div/div[1]/div/div/div/div/div/div/div/div[2]/div[2]/div[1]/div/input')
  File "/home/hlf/crontab/zstuAutoFillOut.py", line 21, in enter
    (By.XPATH, path)))
  File "/home/hlf/.local/lib/python3.6/site-packages/selenium/webdriver/support/wait.py", line 80, in until
    raise TimeoutException(message, screen, stacktrace)
selenium.common.exceptions.TimeoutException: Message: 


During handling of the above exception, another exception occurred:

Traceback (most recent call last):
  File "/home/hlf/crontab/zstuAutoFillOut.py", line 85, in <module>
    zs.run()
  File "/home/hlf/crontab/zstuAutoFillOut.py", line 55, in run
    click(self.wait,'//*[@id="col_2_row_14"]/div/div/div/div/div[1]/div/div[1]')
  File "/home/hlf/crontab/zstuAutoFillOut.py", line 16, in click
    (By.XPATH, path)))
  File "/home/hlf/.local/lib/python3.6/site-packages/selenium/webdriver/support/wait.py", line 80, in until
    raise TimeoutException(message, screen, stacktrace)
selenium.common.exceptions.TimeoutException: Message: 

-----------------------------------------------------------------------------------
-----------------------------------------------------------------------------------
-----------------------------------------------------------------------------------
-----------------------------------------------------------------------------------
-----------------------------------------------------------------------------------

Mon Mar  8 04:30:01 CST 2021
Traceback (most recent call last):
  File "/home/hlf/crontab/zstuAutoFillOut.py", line 77, in <module>
    zs.login1()
  File "/home/hlf/crontab/zstuAutoFillOut.py", line 42, in login1
    enter(self.wait,'2019329621160','//*[@id="app"]/div/div[1]/div/div/div/div/div/div/div/div[2]/div[2]/div[1]/div/input')
  File "/home/hlf/crontab/zstuAutoFillOut.py", line 21, in enter
    (By.XPATH, path)))
  File "/home/hlf/.local/lib/python3.6/site-packages/selenium/webdriver/support/wait.py", line 80, in until
    raise TimeoutException(message, screen, stacktrace)
selenium.common.exceptions.TimeoutException: Message: 


During handling of the above exception, another exception occurred:

Traceback (most recent call last):
  File "/home/hlf/crontab/zstuAutoFillOut.py", line 85, in <module>
    zs.run()
  File "/home/hlf/crontab/zstuAutoFillOut.py", line 55, in run
    click(self.wait,'//*[@id="col_2_row_14"]/div/div/div/div/div[1]/div/div[1]')
  File "/home/hlf/crontab/zstuAutoFillOut.py", line 16, in click
    (By.XPATH, path)))
  File "/home/hlf/.local/lib/python3.6/site-packages/selenium/webdriver/support/wait.py", line 80, in until
    raise TimeoutException(message, screen, stacktrace)
selenium.common.exceptions.TimeoutException: Message: 

-----------------------------------------------------------------------------------
-----------------------------------------------------------------------------------
-----------------------------------------------------------------------------------
-----------------------------------------------------------------------------------
-----------------------------------------------------------------------------------

Mon Mar  8 03:30:01 CST 2021
Traceback (most recent call last):
  File "/home/hlf/crontab/zstuAutoFillOut.py", line 77, in <module>
    zs.login1()
  File "/home/hlf/crontab/zstuAutoFillOut.py", line 42, in login1
    enter(self.wait,'2019329621160','//*[@id="app"]/div/div[1]/div/div/div/div/div/div/div/div[2]/div[2]/div[1]/div/input')
  File "/home/hlf/crontab/zstuAutoFillOut.py", line 21, in enter
    (By.XPATH, path)))
  File "/home/hlf/.local/lib/python3.6/site-packages/selenium/webdriver/support/wait.py", line 80, in until
    raise TimeoutException(message, screen, stacktrace)
selenium.common.exceptions.TimeoutException: Message: 


During handling of the above exception, another exception occurred:

Traceback (most recent call last):
  File "/home/hlf/crontab/zstuAutoFillOut.py", line 85, in <module>
    zs.run()
  File "/home/hlf/crontab/zstuAutoFillOut.py", line 55, in run
    click(self.wait,'//*[@id="col_2_row_14"]/div/div/div/div/div[1]/div/div[1]')
  File "/home/hlf/crontab/zstuAutoFillOut.py", line 16, in click
    (By.XPATH, path)))
  File "/home/hlf/.local/lib/python3.6/site-packages/selenium/webdriver/support/wait.py", line 80, in until
    raise TimeoutException(message, screen, stacktrace)
selenium.common.exceptions.TimeoutException: Message: 

-----------------------------------------------------------------------------------
-----------------------------------------------------------------------------------
-----------------------------------------------------------------------------------
-----------------------------------------------------------------------------------
-----------------------------------------------------------------------------------

Mon Mar  8 02:30:01 CST 2021
Traceback (most recent call last):
  File "/home/hlf/crontab/zstuAutoFillOut.py", line 77, in <module>
    zs.login1()
  File "/home/hlf/crontab/zstuAutoFillOut.py", line 42, in login1
    enter(self.wait,'2019329621160','//*[@id="app"]/div/div[1]/div/div/div/div/div/div/div/div[2]/div[2]/div[1]/div/input')
  File "/home/hlf/crontab/zstuAutoFillOut.py", line 21, in enter
    (By.XPATH, path)))
  File "/home/hlf/.local/lib/python3.6/site-packages/selenium/webdriver/support/wait.py", line 80, in until
    raise TimeoutException(message, screen, stacktrace)
selenium.common.exceptions.TimeoutException: Message: 


During handling of the above exception, another exception occurred:

Traceback (most recent call last):
  File "/home/hlf/crontab/zstuAutoFillOut.py", line 85, in <module>
    zs.run()
  File "/home/hlf/crontab/zstuAutoFillOut.py", line 55, in run
    click(self.wait,'//*[@id="col_2_row_14"]/div/div/div/div/div[1]/div/div[1]')
  File "/home/hlf/crontab/zstuAutoFillOut.py", line 16, in click
    (By.XPATH, path)))
  File "/home/hlf/.local/lib/python3.6/site-packages/selenium/webdriver/support/wait.py", line 80, in until
    raise TimeoutException(message, screen, stacktrace)
selenium.common.exceptions.TimeoutException: Message: 

-----------------------------------------------------------------------------------
-----------------------------------------------------------------------------------
-----------------------------------------------------------------------------------
-----------------------------------------------------------------------------------
-----------------------------------------------------------------------------------

Mon Mar  8 01:30:02 CST 2021
Traceback (most recent call last):
  File "/home/hlf/crontab/zstuAutoFillOut.py", line 88, in <module>
    z2.close()
  File "/home/hlf/.local/lib/python3.6/site-packages/selenium/webdriver/remote/webdriver.py", line 688, in close
    self.execute(Command.CLOSE)
  File "/home/hlf/.local/lib/python3.6/site-packages/selenium/webdriver/remote/webdriver.py", line 321, in execute
    self.error_handler.check_response(response)
  File "/home/hlf/.local/lib/python3.6/site-packages/selenium/webdriver/remote/errorhandler.py", line 242, in check_response
    raise exception_class(message, screen, stacktrace)
selenium.common.exceptions.InvalidSessionIdException: Message: invalid session id

-----------------------------------------------------------------------------------
-----------------------------------------------------------------------------------
-----------------------------------------------------------------------------------
-----------------------------------------------------------------------------------
-----------------------------------------------------------------------------------

Mon Mar  8 00:30:02 CST 2021
Traceback (most recent call last):
  File "/home/hlf/crontab/zstuAutoFillOut.py", line 77, in <module>
    zs.login1()
  File "/home/hlf/crontab/zstuAutoFillOut.py", line 42, in login1
    enter(self.wait,'2019329621160','//*[@id="app"]/div/div[1]/div/div/div/div/div/div/div/div[2]/div[2]/div[1]/div/input')
  File "/home/hlf/crontab/zstuAutoFillOut.py", line 21, in enter
    (By.XPATH, path)))
  File "/home/hlf/.local/lib/python3.6/site-packages/selenium/webdriver/support/wait.py", line 80, in until
    raise TimeoutException(message, screen, stacktrace)
selenium.common.exceptions.TimeoutException: Message: 


During handling of the above exception, another exception occurred:

Traceback (most recent call last):
  File "/home/hlf/crontab/zstuAutoFillOut.py", line 85, in <module>
    zs.run()
  File "/home/hlf/crontab/zstuAutoFillOut.py", line 54, in run
    click(self.wait,'//*[@id="col_0_row_8"]')
  File "/home/hlf/crontab/zstuAutoFillOut.py", line 16, in click
    (By.XPATH, path)))
  File "/home/hlf/.local/lib/python3.6/site-packages/selenium/webdriver/support/wait.py", line 80, in until
    raise TimeoutException(message, screen, stacktrace)
selenium.common.exceptions.TimeoutException: Message: 

-----------------------------------------------------------------------------------
-----------------------------------------------------------------------------------
-----------------------------------------------------------------------------------
-----------------------------------------------------------------------------------
-----------------------------------------------------------------------------------
